Workbook

Sheet Read Me
A2: Vendor Risk Assessment Workbook
B4: MyFirstHack Mentorship · Weekly Project 03 · Third-Party Vendor Risk Assessment
B5: Assess the vendor in the scenario pack by working through the tabs left to right.
B7: HOW TO USE THIS WORKBOOK
B8: 1 · Vendor Profile: record what the vendor does, the data they hold, and their subprocessors.
B9: 2 · Tiering: score inherent risk on four factors; the sheet returns the vendor's tier.
B10: 3 · Questionnaire: for each control, pick a verdict and note the evidence that led you there.
B11: 4 · Findings: log every gap, score likelihood x impact; the rating colours itself.
B12: 5 · Risk Matrix: reference for how scores become Low / Medium / High / Critical.
B13: 6 · Decision: your overall residual-risk view and recommendation.
B15: CELLS YOU FILL IN ARE SHADED YELLOW. Everything else is a heading or a formula, so leave it alone.
B17: THE FOUR VERDICTS (tab 3)
B18: Met: control exists and evidence proves it works.
... B29: Low (1-4)

Sheet 1 · Vendor Profile
A2: 1 · Vendor Profile & Scope
B3: Record the basics from the scenario pack. Yellow cells are yours to complete.
B5: Assessment reference | C5: MTB-TPRM-2026-0417
B6: Vendor name | C6: CloudLedger Technologies Ltd
B7: Service / product | C7: OriginateCloud (SaaS loan origination & document management)
B8: Business process it supports | C8: Retail lending (personal loans and mortgage applications)
B9: Data types held | C9: Customer full name, address, DOB, contact details, income/employment data, bank statements, and scanned ID documents (passports/driving licenses)
B10: Approx. records within 12 months | C10: 40,000+
B11: Is the process critical / important? | C11: Yes
B12: Hosting & region(s) | C12: AWS, single region: eu-west-1 (Ireland)
B13: Subprocessors (fourth parties) | C13: Amazon Web Services (Hosting), VerifyID Ltd (Identity Verification), MailRelay Inc. (Transactional Email), CloudLedger Support (Offshore Desk)
B14: Certifications claimed | C14: SOC 2 Type II, ISO/IEC 27001
B15: Assessor name | C15: Samuel
B16: Assessment date | C16: 46221
B18: Example (delete when you fill yours in):
B19: Vendor name → CloudLedger Technologies Ltd
B20: Data types held → Name, address, DOB, income, bank statements, ID documents

Sheet 2 · Tiering
A2: 2 · Inherent Risk Tiering
B3: Score each factor 1 (low) to 5 (high) in the yellow cells. The tier is calculated for you.
B5: Inherent-risk factor | C5: Score 1-5 | D5: Weight | E5: Weighted
B6: Data sensitivity (PII, financial, special category) | C6: 5 | D6: 0.35 | E6: =C6*D6 -> 1.75
B7: Operational criticality (how critical / hard to pause) | C7: 5 | D7: 0.3 | E7: =C7*D7 -> 1.5
B8: Regulatory exposure (GDPR, DORA, sector rules) | C8: 5 | D8: 0.2 | E8: =C8*D8 -> 1
B9: System / network / data access granted | C9: 4 | D9: 0.15 | E9: =C9*D9 -> 0.6
B10: Weighted inherent-risk score | D10: =SUM(D6:D9) -> 1 | E10: =SUM(E6:E9) -> 4.85
B12: VENDOR TIER | C12: =IF(E10>=4,"CRITICAL",IF(E10>=3,"HIGH",IF(E10>=2,"MEDIUM","LOW"))) -> CRITICAL
B14: Score >= 4.0 Critical · >= 3.0 High · >= 2.0 Medium · < 2.0 Low
B15: The tier sets the minimum evidence you require (see the bank's TPRM policy in the pack).

Sheet 3 · Questionnaire
A2: 3 · Due Diligence Questionnaire
B3: For each control: read the vendor's claim, check the evidence, then fill the yellow Verdict and Assessor note.
B5: Control | C5: Vendor claim (summary) | D5: Evidence ref | E5: Verdict | F5: Assessor note
B6: Section 1 · Governance & policy
B7: Documented, senior-approved infosec policy | C7: Yes, policy provided, Policy is reviewed annually and approved by senior management. | D7: D4 | E7: Partially met | F7: Example: AES-256 at rest confirmed in Q3.1. Leave verdict cells like this.
B8: Policy reviewed at least annually | C8: Yes, annual review | D8: D4 | E8: Partially met | F8: Policy document control (D4) shows it was last reviewed in January 2024, which is over two years out of date as of July 2026.
B9: Named security owner | C9: No dedicated owner; eng leadership | D9: Q1.3 | E9: Not met | F9: Questionnaire response Q1.3 admits there is no dedicated security owner; document owner field on the policy control page (D4) is explicitly left blank.
B10: Section 2 · Access control & identity
B11: MFA on customer application | C11: Yes | D11: SOC2 / Q2.1 | E11: Met | F11: SOC 2 Type II report summary (D1) confirms that multi-factor authentication was fully tested and enforced on the user application during the audit window.
B12: MFA on admin console & VPN | C12: Roadmap; VPN is password-only | D12: D1 / D3-H2 | E12: Not met | F12: SOC 2 report (D1) explicitly lists missing MFA on the internal administrative console as an audit exception; penetration test (D3) High finding H2 confirms it is open and exposed to the internet.
B13: Periodic access recertification | C13: Yes (claimed) | D13: D1 exceptions | E13: Partially met | F13: SOC 2 report (D1) lists a testing exception: for 3 out of 12 quarters sampled, the quarterly user access review was completely missed or delayed past policy timeframes.
B14: No shared / generic admin accounts | C14: Some shared accounts used | D14: Q2.4 | E14: Not met | F14: Questionnaire answer Q2.4 openly admits that shared service and administrative accounts are actively used by the engineering team for day-to-day operational tasks.
B15: Section 3 · Data protection & encryption
B16: Encryption at rest (AES-256) | C16: Yes | D16: Q3.1 | E16: Met | F16: Questionnaire response Q3.1 and contractual terms summary (D7) confirm data is encrypted at rest using AWS-managed AES-256 algorithms.
B17: Encryption in transit (TLS 1.2+) | C17: Yes, customer traffic | D17: Q3.2 / D3-H1 | E17: Partially met | F17: While client-facing traffic utilizes TLS 1.2+ (Q3.2), penetration test finding H1 (D3) shows deprecated TLS 1.0/1.1 protocols remain actively enabled on a legacy support endpoint past the remediation SLA.
B18: PII processed outside UK/EEA controlled | C18: Offshore support has access | D18: B / D7 | E18: Not met | F18: Vendor profile (B) confirms offshore support agents hold unrestricted production access to customer records, but this operation is completely excluded from the SOC 2 (D1) and ISO 27001 (D2) scopes.
B19: Approved transfer mechanism (SCCs) | C19: Referenced, not attached | D19: D7 | E19: Not met | F19: Contractual review (D7) shows that while Standard Contractual Clauses are named in the text, they are not attached, and no mandatory Transfer Risk Assessment (TRA) has been executed.
B20: Defined retention schedule | C20: 'As long as necessary' | D20: D7 | E20: Not met | F20: Contract terms (D7) state data is held vague as 'as long as necessary to provide the service', failing to establish a concrete regulatory retention and deletion schedule.
B21: Section 4 · Vulnerability & patch mgmt
B22: Regular vulnerability scanning | C22: Yes, monthly | D22: Q4.1 | E22: Met | F22: Questionnaire response Q4.1 claims automated scanning runs monthly; no exceptions or failures regarding internal automated scans are logged within the compliance files.
B23: Annual independent pen test | C23: Yes (but 14 months old) | D23: D3 | E23: Partially met | F23: The external penetration test document provided (D3) is dated May 2025, meaning the assessment has gone stale and sits past the strict 12-month annual requirement as of July 2026.
B24: Pen-test findings remediated in SLA | C24: 2 High findings still open | D24: D3 | E24: Not met | F24: Penetration test ledger (D3) reveals two High-severity findings (H1 and H2) have been left open and unmitigated, blowing completely past the corporate 90-day remediation SLA window.
B25: Section 5 · Secure development
B26: Secure SDLC with code review | C26: Yes, PR review | D26: Q5.1 | E26: Met | F26: Verified via questionnaire response Q5.1; all software codebase mutations are gate-kept by strict peer pull-request review mandates prior to production merges.
B27: Environments separated | C27: Yes | D27: Q5.2 | E27: Met | F27: Confirmed via response Q5.2; logical architectural environment isolation boundaries are enforced directly at the AWS cloud layer.
B28: Section 6 · Logging, monitoring & IR
B29: Documented incident response plan | C29: Yes | D29: D5 | E29: Met | F29: Incident Response Plan extract (D5) confirms a structured policy exists detailing P1–P4 severity triggers and an escalation pathway to engineering on-call groups.
B30: Committed breach-notification timeframe | C30: 'Promptly', no SLA | D30: D5 / D7 | E30: Not met | F30: Incident policy (D5) and legal contract draft (D7) explicitly rely on ambiguous phrasing ('promptly' / 'without undue delay') rather than committing to a hard 24/48/72-hour notification SLA required by the bank.
B31: IR plan tested in last 12 months | C31: No record provided | D31: D5 | E31: Not met | F31: Incident response policy control log (D5) notes that exercises should be run 'periodically', but no record of a tabletop or live drill has been produced for the last 12 months.
B32: Section 7 · Business continuity & DR
B33: Documented RTO / RPO | C33: RTO 8h / RPO 4h | D33: D6 | E33: Met | F33: Corporate DR policy overview sheet (D6) explicitly defines and commits to operational recovery objectives of an 8-hour RTO and a 4-hour RPO.
B34: Multi-region failover | C34: Single region eu-west-1 | D34: D6 | E34: Not met | F34: Architecture brief (D6) confirms the application is isolated solely within AWS Ireland (eu-west-1). Zero secondary cross-region failover capacities are configured.
B35: DR test in last 12 months | C35: Last test Feb 2024 | D35: D6 | E35: Not met | F35: Disaster recovery ledger (D6) indicates the last partial test execution occurred back in February 2024. No comprehensive failover or validation drill has run for over 28 months.
B36: Section 8 · Fourth-party management
B37: Subprocessor list maintained | C37: Yes | D37: B | E37: Met | F37: The vendor maintains a clear, consolidated fourth-party infrastructure map in Section B, identifying AWS, VerifyID, MailRelay, and their offshore delivery vendor.
B38: Security obligations flowed down & assessed | C38: Not evidenced for offshore | D38: Q8.2 | E38: Partially met | F38: While baseline legal flow-downs exist for standardized hyper-scalers like AWS (Q8.2), security checks and vetting evaluations are completely unevidenced for their offshore support partner.
B39: Section 9 · Compliance & assurance
B40: Current SOC 2 (type & scope adequate) | C40: Type II, Security only, stale | D40: D1 | E40: Partially met | F40: The SOC 2 report (D1) is real and is a Type II, but its scope is limited strictly to the Security criterion and completely excludes the high-risk offshore operations boundary.
B41: Current ISO 27001 (scope adequate) | C41: Excludes offshore; expires soon | D41: D2 | E41: Partially met | F41: The ISO certification (D2) is active until August 2026, but the official Statement of Applicability explicitly excludes the offshore customer support center from its compliance perimeter.
B42: Right to audit granted | C42: No, SOC 2 offered instead | D42: D7 | E42: Not met | F42: DPA contractual terms audit (D7) demonstrates that a Right to Audit clause is absent; the vendor forces the customer to accept stagnant SOC 2 reports in its place.
...

Sheet 4 · Findings
A2: 4 · Findings Register
B3: Add one row per gap. Enter Likelihood and Impact (1-5). Score and Rating fill in and colour automatically.
B5: ID | C5: Domain | D5: Finding | E5: Owner | F5: Likelihood 1-5 | G5: Impact 1-5 | H5: Score | I5: Rating | J5: Recommendation | K5: Due date | L5: Status
B6: F1 | C6: BC / DR (Section 7) | D6: No evidenced DR/failover test in >12 months; single AWS region, no cross-region failover. | E6: Vendor | F6: 4 | G6: 5 | H6: =IF(OR(F6="",G6=""),"",F6*G6) -> 20 | I6: =IF(H6="","",IF(H6>=15,"Critical",IF(H6>=10,"High",IF(H6>=5,"Medium","Low")))) -> Critical | J6: Configure cross-region failover; run and evidence a full DR test. | K6: 30 days | L6: Open
C7: Access Control & Identity (Section 2) | D7: The internal administrative console is reachable from the public internet with no multi-factor authentication (MFA) enforced. This is a critical exposure that has breached the vendor's 90-day remediation SLA (Pen-test finding H2). | E7: Vendor | F7: 5 | G7: 5 | H7: =IF(OR(F7="",G7=""),"",F7*G7) -> 25 | I7: =IF(H7="","",IF(H7>=15,"Critical",IF(H7>=10,"High",IF(H7>=5,"Medium","Low")))) -> Critical | J7: Vendor must restrict administrative console access to corporate IP ranges or VPN gateways and enforce mandatory MFA before live data syncing. | K7: Pre-onboarding | L7: Open
C8: Compliance & Assurance (Section 9) | D8: Offshore customer support agents have full production access to customer records, but this operation is completely excluded from the scope of both the SOC 2 Type II and ISO 27001 certifications. Required Standard Contractual Clauses (SCCs) are missing from the draft agreement. | E8: Vendor + Bank | F8: 4 | G8: 4 | H8: =IF(OR(F8="",G8=""),"",F8*G8) -> 16 | I8: =IF(H8="","",IF(H8>=15,"Critical",IF(H8>=10,"High",IF(H8>=5,"Medium","Low")))) -> Critical | J8: The bank must legally bind the vendor to executed SCCs. The vendor must commit to expanding the scope of their next annual SOC 2/ISO audits to include the offshore facility. | K8: 60 days post-contract | L8: Open
C9: Governance & Policy (Section 1) | D9: The corporate Information Security Policy is stale, having last been reviewed in January 2024. The document control page lacks a defined owner and holds no record of senior management sign-off. | E9: Vendor | F9: 3 | G9: 2 | H9: =IF(OR(F9="",G9=""),"",F9*G9) -> 6 | I9: =IF(H9="","",IF(H9>=15,"Critical",IF(H9>=10,"High",IF(H9>=5,"Medium","Low")))) -> Medium | J9: Vendor must update, assign an owner, and obtain executive management sign-off for their Information Security Policy. | K9: 90 days post-contract | L9: Open
H10: =IF(OR(F10="",G10=""),"",F10*G10) | I10: =IF(H10="","",IF(H10>=15,"Critical",IF(H10>=10,"High",IF(H10>=5,"Medium","Low"))))
H11: =IF(OR(F11="",G11=""),"",F11*G11) | I11: =IF(H11="","",IF(H11>=15,"Critical",IF(H11>=10,"High",IF(H11>=5,"Medium","Low"))))
H12: =IF(OR(F12="",G12=""),"",F12*G12) | I12: =IF(H12="","",IF(H12>=15,"Critical",IF(H12>=10,"High",IF(H12>=5,"Medium","Low"))))
H13: =IF(OR(F13="",G13=""),"",F13*G13) | I13: =IF(H13="","",IF(H13>=15,"Critical",IF(H13>=10,"High",IF(H13>=5,"Medium","Low"))))
H14: =IF(OR(F14="",G14=""),"",F14*G14) | I14: =IF(H14="","",IF(H14>=15,"Critical",IF(H14>=10,"High",IF(H14>=5,"Medium","Low"))))
H15: =IF(OR(F15="",G15=""),"",F15*G15) | I15: =IF(H15="","",IF(H15>=15,"Critical",IF(H15>=10,"High",IF(H15>=5,"Medium","Low"))))
H16: =IF(OR(F16="",G16=""),"",F16*G16) | I16: =IF(H16="","",IF(H16>=15,"Critical",IF(H16>=10,"High",IF(H16>=5,"Medium","Low"))))
H17: =IF(OR(F17="",G17=""),"",F17*G17) | I17: =IF(H17="","",IF(H17>=15,"Critical",IF(H17>=10,"High",IF(H17>=5,"Medium","Low"))))
H18: =IF(OR(F18="",G18=""),"",F18*G18) | I18: =IF(H18="","",IF(H18>=15,"Critical",IF(H18>=10,"High",IF(H18>=5,"Medium","Low"))))
H19: =IF(OR(F19="",G19=""),"",F19*G19) | I19: =IF(H19="","",IF(H19>=15,"Critical",IF(H19>=10,"High",IF(H19>=5,"Medium","Low"))))
H20: =IF(OR(F20="",G20=""),"",F20*G20) | I20: =IF(H20="","",IF(H20>=15,"Critical",IF(H20>=10,"High",IF(H20>=5,"Medium","Low"))))
H21: =IF(OR(F21="",G21=""),"",F21*G21) | I21: =IF(H21="","",IF(H21>=15,"Critical",IF(H21>=10,"High",IF(H21>=5,"Medium","Low"))))
... H25: =IF(OR(F25="",G25=""),"",F25*G25) | I25: =IF(H25="","",IF(H25>=15,"Critical",IF(H25>=10,"High",IF(H25>=5,"Medium","Low"))))

Sheet 5 · Risk Matrix
A2: 5 · Risk Rating Matrix (Likelihood x Impact)
B5: Impact ↓ / Likelihood → | C5: 1 Rare | D5: 2 Unlikely | E5: 3 Possible | F5: 4 Likely | G5: 5 Almost certain
B6: 5 Severe | C6: 5 | D6: 10 | E6: 15 | F6: 20 | G6: 25
B7: 4 Major | C7: 4 | D7: 8 | E7: 12 | F7: 16 | G7: 20
B8: 3 Moderate | C8: 3 | D8: 6 | E8: 9 | F8: 12 | G8: 15
B9: 2 Minor | C9: 2 | D9: 4 | E9: 6 | F9: 8 | G9: 10
B10: 1 Negligible | C10: 1 | D10: 2 | E10: 3 | F10: 4 | G10: 5
B13: Rating bands
B14: Low (1-4)
B15: Medium (5-9)
B16: High (10-14)
B17: Critical (15-25)

Sheet 6 · Decision
A2: 6 · Assessment Decision
B3: Pull it together. Findings counts fill in automatically; yellow cells are your judgement.
B5: Vendor tier | C5: ='2 · Tiering'!C12 -> CRITICAL
B6: Critical findings | C6: =COUNTIF('4 · Findings'!I6:I25,"Critical") -> 3
B7: High findings | C7: =COUNTIF('4 · Findings'!I6:I25,"High") -> 0
B8: Medium findings | C8: =COUNTIF('4 · Findings'!I6:I25,"Medium") -> 1
B9: Low findings | C9: =COUNTIF('4 · Findings'!I6:I25,"Low") -> 0
B10: Overall residual risk (your view) | C10: CRITICAL
B11: Within the bank's risk appetite? | C11: No
B12: Recommendation | C12: Approve with conditions
B13: Conditions / remediation deadline | C13: Onboarding is blocked until Critical Findings F1 (Business Continuity testing) and F2 (Exposed Administrative MFA) are fully remediated and verified via technical evidence. High and Medium findings must be resolved under contractual SLAs within 60 days of signing.
B14: Accountable risk owner | C14: Head of Risk
B15: Decision date
B17: Reminder
B18: Meridian will not accept any open Critical finding on a critical-function vendor.
B19: The assessor recommends; the accountable risk owner decides.
